<?xml version="1.0"?>
<robot name="pfe_robot">

  <!-- ===================== WORLD ===================== -->
  <link name="map"/>

  <!-- ===================== ROS BASE ===================== -->
  <link name="base_link"/>

  <joint name="map_to_base" type="fixed">
    <parent link="map"/>
    <child link="base_link"/>
    <origin xyz="0 0 0" rpy="0 0 0"/>
  </joint>

  <!-- ===================== CAD WRAPPER ===================== -->
  <link name="base_cad">
    <inertial>
      <origin xyz="-0.1806532478764334 0.10959136535685834 -0.09958100133613353" rpy="0 0 0"/>
      <mass value="10.846844826170994"/>
      <inertia ixx="0.1137300898429841" iyy="0.15506270343665957" izz="0.1525596007466387"
               ixy="0.0002636196730894534" iyz="0.0002706724915273537" ixz="0.008689234245133912"/>
    </inertial>

    <visual>
      <origin xyz="0 0 0" rpy="0 0 0"/>
      <geometry>
        <mesh filename="package://pfe/meshes/base_link-v5.stl" scale="0.001 0.001 0.001"/>
      </geometry>
    </visual>

    <collision>
      <origin xyz="0 0 0" rpy="0 0 0"/>
      <geometry>
        <mesh filename="package://pfe/meshes/base_link-v5.stl" scale="0.001 0.001 0.001"/>
      </geometry>
    </collision>
  </link>

  <!-- Fusion: +x backward, +y right -->
  <joint name="base_to_cad" type="fixed">
    <parent link="base_link"/>
    <child link="base_cad"/>
    <origin xyz="0 0 0" rpy="0 0 3.141592653589793"/>
  </joint>

  <!-- ===================== ARM ===================== -->
  <link name="arm_link">
    <inertial>
      <origin xyz="-2.2902735970831146e-07 0.0017334076218106455 0.0365000048213585" rpy="0 0 0"/>
      <mass value="0.5338474560099968"/>
      <inertia ixx="0.00022030891025364568" iyy="0.0011328418152016656" izz="0.0009599083468218444"
               ixy="9.724324401272355e-10" iyz="-5.204170427930421e-18" ixz="-5.898059818321144e-17"/>
    </inertial>

    <visual>
      <origin xyz="9.349037100037094e-10 0.004999995232077037 0.03650000482135752"
              rpy="1.5707963267948963 1.5707963267948957 0"/>
      <geometry>
        <mesh filename="package://pfe/meshes/arm_link-v1.stl" scale="0.001 0.001 0.001"/>
      </geometry>
    </visual>

    <collision>
      <origin xyz="9.349037100037094e-10 0.004999995232077037 0.03650000482135752"
              rpy="1.5707963267948963 1.5707963267948957 0"/>
      <geometry>
        <mesh filename="package://pfe/meshes/arm_link-v1.stl" scale="0.001 0.001 0.001"/>
      </geometry>
    </collision>
  </link>

  <joint name="arm_joint" type="continuous">
    <parent link="base_cad"/>
    <child link="arm_link"/>
    <origin xyz="-0.3689156752862411 0.07293206200904699 -0.14265636918407304"
            rpy="-1.5707963267948974 -1.5265566588595922e-16 7.21644966006352e-16"/>
    <axis xyz="0 0 1"/>
  </joint>

  <!-- ===================== FLIPPER ===================== -->
  <link name="flipper_link">
    <inertial>
      <origin xyz="2.6474475234294913e-09 4.767925592119582e-09 -0.07580524145430977" rpy="0 0 0"/>
      <mass value="0.4797185340176825"/>
      <inertia ixx="0.0011969873864993257" iyy="0.0009456324882451857" izz="0.0002533232197152197"
               ixy="-1.3010426069826053e-18" iyz="1.734723475976807e-18" ixz="1.7802599672211983e-16"/>
    </inertial>

    <visual>
      <origin xyz="0.00861550378970137 0.01247089554740951 -0.07550000482135592"
              rpy="-1.5707963267948968 -1.5707963267947291 0"/>
      <geometry>
        <mesh filename="package://pfe/meshes/flipper_link-v1.stl" scale="0.001 0.001 0.001"/>
      </geometry>
    </visual>

    <collision>
      <origin xyz="0.00861550378970137 0.01247089554740951 -0.07550000482135592"
              rpy="-1.5707963267948968 -1.5707963267947291 0"/>
      <geometry>
        <mesh filename="package://pfe/meshes/flipper_link-v1.stl" scale="0.001 0.001 0.001"/>
      </geometry>
    </collision>
  </link>

  <joint name="flipper_joint" type="continuous">
    <parent link="base_cad"/>
    <child link="flipper_link"/>
    <origin xyz="-0.0164154352862412 0.03393206200904719 -0.13965336918407295"
            rpy="1.5707963267948957 -1.5265566588595922e-16 7.21644966006352e-16"/>
    <axis xyz="0 0 1"/>
  </joint>

  <!-- ===================== MECANUM WHEELS ===================== -->
  <link name="front_left_wheel_link">
    <visual>
      <geometry>
        <mesh filename="package://pfe/meshes/wheel_link-v1.stl" scale="0.001 0.001 0.001"/>
      </geometry>
    </visual>
    <collision>
      <geometry>
        <mesh filename="package://pfe/meshes/wheel_link-v1.stl" scale="0.001 0.001 0.001"/>
      </geometry>
    </collision>
  </link>

  <link name="rear_left_wheel_link">
    <visual>
      <geometry>
        <mesh filename="package://pfe/meshes/wheel_link-v1.stl" scale="0.001 0.001 0.001"/>
      </geometry>
    </visual>
    <collision>
      <geometry>
        <mesh filename="package://pfe/meshes/wheel_link-v1.stl" scale="0.001 0.001 0.001"/>
      </geometry>
    </collision>
  </link>

  <link name="rear_right_wheel_link">
    <visual>
      <geometry>
        <mesh filename="package://pfe/meshes/wheel_link-v1.stl" scale="0.001 0.001 0.001"/>
      </geometry>
    </visual>
    <collision>
      <geometry>
        <mesh filename="package://pfe/meshes/wheel_link-v1.stl" scale="0.001 0.001 0.001"/>
      </geometry>
    </collision>
  </link>

  <link name="front_right_wheel_link">
    <visual>
      <geometry>
        <mesh filename="package://pfe/meshes/wheel_link-v1.stl" scale="0.001 0.001 0.001"/>
      </geometry>
    </visual>
    <collision>
      <geometry>
        <mesh filename="package://pfe/meshes/wheel_link-v1.stl" scale="0.001 0.001 0.001"/>
      </geometry>
    </collision>
  </link>

  <joint name="front_left_wheel_joint" type="continuous">
    <parent link="base_cad"/>
    <child link="front_left_wheel_link"/>
    <origin xyz="-0.2329295352862411 -0.01429999799095302 -0.15665336918407297"
            rpy="1.5707963267948957 -1.5265566588595922e-16 7.21644966006352e-16"/>
    <axis xyz="0 0 1"/>
  </joint>

  <joint name="rear_left_wheel_joint" type="continuous">
    <parent link="base_cad"/>
    <child link="rear_left_wheel_link"/>
    <origin xyz="-0.10492999528624117 -0.01429999799095293 -0.1566533691840729"
            rpy="1.5707963267948957 -1.5265566588595922e-16 7.21644966006352e-16"/>
    <axis xyz="0 0 1"/>
  </joint>

  <joint name="rear_right_wheel_joint" type="continuous">
    <parent link="base_cad"/>
    <child link="rear_right_wheel_link"/>
    <origin xyz="-0.10490178528624114 0.23430000200904744 -0.15665336918407313"
            rpy="-1.5707963267948941 -1.5265566588595922e-16 7.21644966006352e-16"/>
    <axis xyz="0 0 1"/>
  </joint>

  <joint name="front_right_wheel_joint" type="continuous">
    <parent link="base_cad"/>
    <child link="front_right_wheel_link"/>
    <origin xyz="-0.23290132528624108 0.23430000200904733 -0.15665336918407316"
            rpy="-1.5707963267948974 -1.5265566588595922e-16 7.21644966006352e-16"/>
    <axis xyz="0 0 1"/>
  </joint>

 
  <!-- ===================== CAMERA ===================== -->
  <link name="arducam_link">
    <inertial>
      <origin xyz="-0.00013322161290098224 0.0009504573350092649 0.00043137020324471645" rpy="0 0 0"/>
      <mass value="0.0010174438167060709"/>
      <inertia ixx="4.5307132551562007e-08" iyy="3.5090242032863035e-08" izz="7.59611441794051e-08"
               ixy="1.0347644394329782e-09" iyz="-2.264070327162072e-09" ixz="1.3166586418150303e-10"/>
    </inertial>

    <visual>
      <origin xyz="-2.352010142203653e-10 4.813011784676747e-09 -0.001750004628485895"
              rpy="8.52607141014584e-18 -5.5511151231257815e-17 9.485990215114392e-16"/>
      <geometry>
        <mesh filename="package://pfe/meshes/arducam_link-v3.stl" scale="0.001 0.001 0.001"/>
      </geometry>
    </visual>

    <collision>
      <origin xyz="-2.352010142203653e-10 4.813011784676747e-09 -0.001750004628485895"
              rpy="8.52607141014584e-18 -5.5511151231257815e-17 9.485990215114392e-16"/>
      <geometry>
        <mesh filename="package://pfe/meshes/arducam_link-v3.stl" scale="0.001 0.001 0.001"/>
      </geometry>
    </collision>
  </link>

  <joint name="base_to_arducam" type="fixed">
    <parent link="base_cad"/>
    <child link="arducam_link"/>
    <origin xyz="-0.10964196528624118 0.10993206200904702 0.15264326081592658"
            rpy="-3.1415926535897922 -0.6973907898697068 -3.141592653589792"/>
  </joint>

  <!-- ROS optical frame for camera-based vision -->
  <link name="arducam_optical_frame"/>

  <joint name="arducam_to_optical" type="fixed">
    <parent link="arducam_link"/>
    <child link="arducam_optical_frame"/>
    <origin xyz="0 0 0" rpy="-1.57079632679 0 -1.57079632679"/>
  </joint>

  <!-- ===================== SUCTION CUPS ===================== -->
  <link name="cup_0">
    <visual>
      <geometry>
        <mesh filename="package://pfe/meshes/suctioncup_link-v1.stl" scale="0.001 0.001 0.001"/>
      </geometry>
    </visual>
    <collision>
      <geometry>
        <mesh filename="package://pfe/meshes/suctioncup_link-v1.stl" scale="0.001 0.001 0.001"/>
      </geometry>
    </collision>
  </link>

  <link name="cup_1">
    <visual>
      <geometry>
        <mesh filename="package://pfe/meshes/suctioncup_link-v1.stl" scale="0.001 0.001 0.001"/>
      </geometry>
    </visual>
    <collision>
      <geometry>
        <mesh filename="package://pfe/meshes/suctioncup_link-v1.stl" scale="0.001 0.001 0.001"/>
      </geometry>
    </collision>
  </link>

  <link name="cup_2">
    <visual>
      <geometry>
        <mesh filename="package://pfe/meshes/suctioncup_link-v1.stl" scale="0.001 0.001 0.001"/>
      </geometry>
    </visual>
    <collision>
      <geometry>
        <mesh filename="package://pfe/meshes/suctioncup_link-v1.stl" scale="0.001 0.001 0.001"/>
      </geometry>
    </collision>
  </link>

  <link name="cup_3">
    <visual>
      <geometry>
        <mesh filename="package://pfe/meshes/suctioncup_link-v1.stl" scale="0.001 0.001 0.001"/>
      </geometry>
    </visual>
    <collision>
      <geometry>
        <mesh filename="package://pfe/meshes/suctioncup_link-v1.stl" scale="0.001 0.001 0.001"/>
      </geometry>
    </collision>
  </link>

  <joint name="arm_to_cup_0" type="fixed">
    <parent link="arm_link"/>
    <child link="cup_0"/>
    <origin xyz="0.075 0.0105 0.0365" rpy="1.5707963267948966 0 0"/>
  </joint>

  <joint name="arm_to_cup_1" type="fixed">
    <parent link="arm_link"/>
    <child link="cup_1"/>
    <origin xyz="0.025 0.0100 0.0365" rpy="-1.5707963267948966 0 0"/>
  </joint>

  <joint name="arm_to_cup_2" type="fixed">
    <parent link="arm_link"/>
    <child link="cup_2"/>
    <origin xyz="-0.025 0.0105 0.0365" rpy="1.5707963267948966 0 0"/>
  </joint>

  <joint name="arm_to_cup_3" type="fixed">
    <parent link="arm_link"/>
    <child link="cup_3"/>
    <origin xyz="-0.075 0.0105 0.0365" rpy="1.5707963267948966 0 0"/>
  </joint>

</robot>