<?xml version="1.0"?>
<robot name="pfe_robot">

  <!-- ===================== WORLD ===================== -->
  <link name="map"/>

  <!-- ===================== ROS BASE ===================== -->
  <link name="base_link"/>

  <joint name="map_to_base" type="fixed">
    <parent link="map"/>
    <child link="base_link"/>
    <origin xyz="0 0 0" rpy="0 0 0"/>
  </joint>

  <!-- ===================== CAD WRAPPER (Fusion frame) ===================== -->
  <link name="base_cad">
    <inertial>
      <origin xyz="-0.181130474842482 0.10958995900517023 -0.10051074270429218" rpy="0 0 0"/>
      <mass value="10.802255131301344"/>
      <inertia ixx="0.11142549471720897" iyy="0.15234586542751433" izz="0.15214678916514196"
               ixy="0.0002653832816470656" iyz="0.00027410838368888666" ixz="0.009773387741291757"/>
    </inertial>

    <visual>
      <origin xyz="0 0 0" rpy="0 0 0"/>
      <geometry>
        <mesh filename="package://pfe/meshes/base_link-v3.stl" scale="0.001 0.001 0.001"/>
      </geometry>
    </visual>

    <collision>
      <origin xyz="0 0 0" rpy="0 0 0"/>
      <geometry>
        <mesh filename="package://pfe/meshes/base_link-v3.stl" scale="0.001 0.001 0.001"/>
      </geometry>
    </collision>
  </link>

  <!-- Fusion: +x backward, +y right -->
  <joint name="base_to_cad" type="fixed">
    <parent link="base_link"/>
    <child link="base_cad"/>
    <origin xyz="0 0 0" rpy="0 0 3.141592653589793"/>
  </joint>

  <!-- ===================== ARM ===================== -->
  <link name="arm_link">
    <inertial>
      <origin xyz="-2.2902735970831146e-07 0.0017334076218106455 0.0365000048213585" rpy="0 0 0"/>
      <mass value="0.5338474560099968"/>
      <inertia ixx="0.00022030891025364568" iyy="0.0011328418152016656" izz="0.0009599083468218444"
               ixy="9.724324401272355e-10" iyz="-5.204170427930421e-18" ixz="-5.898059818321144e-17"/>
    </inertial>

    <visual>
      <origin xyz="9.349037100037094e-10 0.004999995232077037 0.03650000482135752"
              rpy="1.5707963267948963 1.5707963267948957 0"/>
      <geometry>
        <mesh filename="package://pfe/meshes/arm_link-v1.stl" scale="0.001 0.001 0.001"/>
      </geometry>
    </visual>

    <collision>
      <origin xyz="9.349037100037094e-10 0.004999995232077037 0.03650000482135752"
              rpy="1.5707963267948963 1.5707963267948957 0"/>
      <geometry>
        <mesh filename="package://pfe/meshes/arm_link-v1.stl" scale="0.001 0.001 0.001"/>
      </geometry>
    </collision>
  </link>

  <joint name="arm_joint" type="continuous">
    <parent link="base_cad"/>
    <child link="arm_link"/>
    <origin xyz="-0.3689156752862411 0.07293206200904699 -0.14265636918407304"
            rpy="-1.5707963267948974 -1.5265566588595922e-16 7.21644966006352e-16"/>
    <axis xyz="0 0 1"/>
  </joint>

  <!-- ===================== FLIPPER ===================== -->
  <link name="flipper_link">
    <inertial>
      <origin xyz="2.6474475234294913e-09 4.767925592119582e-09 -0.07580524145430977" rpy="0 0 0"/>
      <mass value="0.4797185340176825"/>
      <inertia ixx="0.0011969873864993257" iyy="0.0009456324882451857" izz="0.0002533232197152197"
               ixy="-1.3010426069826053e-18" iyz="1.734723475976807e-18" ixz="1.7802599672211983e-16"/>
    </inertial>

    <visual>
      <origin xyz="0.00861550378970137 0.01247089554740951 -0.07550000482135592"
              rpy="-1.5707963267948968 -1.5707963267947291 0"/>
      <geometry>
        <mesh filename="package://pfe/meshes/flipper_link-v1.stl" scale="0.001 0.001 0.001"/>
      </geometry>
    </visual>

    <collision>
      <origin xyz="0.00861550378970137 0.01247089554740951 -0.07550000482135592"
              rpy="-1.5707963267948968 -1.5707963267947291 0"/>
      <geometry>
        <mesh filename="package://pfe/meshes/flipper_link-v1.stl" scale="0.001 0.001 0.001"/>
      </geometry>
    </collision>
  </link>

  <joint name="flipper_joint" type="continuous">
    <parent link="base_cad"/>
    <child link="flipper_link"/>
    <origin xyz="-0.0164154352862412 0.03393206200904719 -0.13965336918407295"
            rpy="1.5707963267948957 -1.5265566588595922e-16 7.21644966006352e-16"/>
    <axis xyz="0 0 1"/>
  </joint>

  <!-- ===================== MECANUM WHEELS ===================== -->
  <link name="front_left_wheel_link">
    <visual><geometry><mesh filename="package://pfe/meshes/wheel_link-v1.stl" scale="0.001 0.001 0.001"/></geometry></visual>
    <collision><geometry><mesh filename="package://pfe/meshes/wheel_link-v1.stl" scale="0.001 0.001 0.001"/></geometry></collision>
  </link>

  <link name="rear_left_wheel_link">
    <visual><geometry><mesh filename="package://pfe/meshes/wheel_link-v1.stl" scale="0.001 0.001 0.001"/></geometry></visual>
    <collision><geometry><mesh filename="package://pfe/meshes/wheel_link-v1.stl" scale="0.001 0.001 0.001"/></geometry></collision>
  </link>

  <link name="rear_right_wheel_link">
    <visual><geometry><mesh filename="package://pfe/meshes/wheel_link-v1.stl" scale="0.001 0.001 0.001"/></geometry></visual>
    <collision><geometry><mesh filename="package://pfe/meshes/wheel_link-v1.stl" scale="0.001 0.001 0.001"/></geometry></collision>
  </link>

  <link name="front_right_wheel_link">
    <visual><geometry><mesh filename="package://pfe/meshes/wheel_link-v1.stl" scale="0.001 0.001 0.001"/></geometry></visual>
    <collision><geometry><mesh filename="package://pfe/meshes/wheel_link-v1.stl" scale="0.001 0.001 0.001"/></geometry></collision>
  </link>

  <joint name="front_left_wheel_joint" type="continuous">
    <parent link="base_cad"/>
    <child link="front_left_wheel_link"/>
    <origin xyz="-0.2329295352862411 -0.01429999799095302 -0.15665336918407297"
            rpy="1.5707963267948957 -1.5265566588595922e-16 7.21644966006352e-16"/>
    <axis xyz="0 0 1"/>
  </joint>

  <joint name="rear_left_wheel_joint" type="continuous">
    <parent link="base_cad"/>
    <child link="rear_left_wheel_link"/>
    <origin xyz="-0.10492999528624117 -0.01429999799095293 -0.1566533691840729"
            rpy="1.5707963267948957 -1.5265566588595922e-16 7.21644966006352e-16"/>
    <axis xyz="0 0 1"/>
  </joint>

  <joint name="rear_right_wheel_joint" type="continuous">
    <parent link="base_cad"/>
    <child link="rear_right_wheel_link"/>
    <origin xyz="-0.10490178528624114 0.23430000200904744 -0.15665336918407313"
            rpy="-1.5707963267948941 -1.5265566588595922e-16 7.21644966006352e-16"/>
    <axis xyz="0 0 1"/>
  </joint>

  <joint name="front_right_wheel_joint" type="continuous">
    <parent link="base_cad"/>
    <child link="front_right_wheel_link"/>
    <origin xyz="-0.23290132528624108 0.23430000200904733 -0.15665336918407316"
            rpy="-1.5707963267948974 -1.5265566588595922e-16 7.21644966006352e-16"/>
    <axis xyz="0 0 1"/>
  </joint>

  <!-- ===================== CAMERA ===================== -->
  <link name="arducam_link">
    <visual>
      <origin xyz="1.7220046188981542e-09 4.813011891258156e-09 -0.0017500015693401494"
              rpy="4.31077779183057e-16 1.6653345369377346e-16 -3.1415926535897927"/>
      <geometry>
        <mesh filename="package://pfe/meshes/arducam_link-v3.stl" scale="0.001 0.001 0.001"/>
      </geometry>
    </visual>
    <collision>
      <origin xyz="1.7220046188981542e-09 4.813011891258156e-09 -0.0017500015693401494"
              rpy="4.31077779183057e-16 1.6653345369377346e-16 -3.1415926535897927"/>
      <geometry>
        <mesh filename="package://pfe/meshes/arducam_link-v3.stl" scale="0.001 0.001 0.001"/>
      </geometry>
    </collision>
  </link>

  <joint name="base_to_arducam" type="fixed">
    <parent link="base_cad"/>
    <child link="arducam_link"/>
    <origin xyz="-0.21195906528624112 0.10993206200904702 0.0426585308159267"
            rpy="-3.141592653589791 -1.178097245096172 -3.141592653589791"/>
  </joint>

  <!-- ===================== SUCTION CUPS ===================== -->
  <!-- arm_link IS the intake bar -->

  <link name="cup_0">
    <visual><geometry><mesh filename="package://pfe/meshes/suctioncup_link-v1.stl" scale="0.001 0.001 0.001"/></geometry></visual>
    <collision><geometry><mesh filename="package://pfe/meshes/suctioncup_link-v1.stl" scale="0.001 0.001 0.001"/></geometry></collision>
  </link>

  <link name="cup_1">
    <visual><geometry><mesh filename="package://pfe/meshes/suctioncup_link-v1.stl" scale="0.001 0.001 0.001"/></geometry></visual>
    <collision><geometry><mesh filename="package://pfe/meshes/suctioncup_link-v1.stl" scale="0.001 0.001 0.001"/></geometry></collision>
  </link>

  <link name="cup_2">
    <visual><geometry><mesh filename="package://pfe/meshes/suctioncup_link-v1.stl" scale="0.001 0.001 0.001"/></geometry></visual>
    <collision><geometry><mesh filename="package://pfe/meshes/suctioncup_link-v1.stl" scale="0.001 0.001 0.001"/></geometry></collision>
  </link>

  <link name="cup_3">
    <visual><geometry><mesh filename="package://pfe/meshes/suctioncup_link-v1.stl" scale="0.001 0.001 0.001"/></geometry></visual>
    <collision><geometry><mesh filename="package://pfe/meshes/suctioncup_link-v1.stl" scale="0.001 0.001 0.001"/></geometry></collision>
  </link>

  <!-- Keep your exact fixed transforms -->
  <joint name="arm_to_cup_0" type="fixed">
    <parent link="arm_link"/>
    <child link="cup_0"/>
    <origin xyz="0.075 0.0105 0.0365" rpy="1.5707963267948966 0 0"/>
  </joint>

  <joint name="arm_to_cup_1" type="fixed">
    <parent link="arm_link"/>
    <child link="cup_1"/>
    <origin xyz="0.025 0.0100 0.0365" rpy="-1.5707963267948966 0 0"/>
  </joint>

  <joint name="arm_to_cup_2" type="fixed">
    <parent link="arm_link"/>
    <child link="cup_2"/>
    <origin xyz="-0.025 0.0105 0.0365" rpy="1.5707963267948966 0 0"/>
  </joint>

  <joint name="arm_to_cup_3" type="fixed">
    <parent link="arm_link"/>
    <child link="cup_3"/>
    <origin xyz="-0.075 0.0105 0.0365" rpy="1.5707963267948966 0 0"/>
  </joint>

</robot>